{
	"bugzilla": {
		"description": "CVE-2020-15801 python: sys.path allowing code to be loaded from arbitrary locations",
		"id": "1860242",
		"url": "https://bugzilla.redhat.com/show_bug.cgi?id=1860242"
	},
	"csaw": false,
	"cvss3": {
		"cvss3_base_score": "8.4",
		"cvss3_scoring_vector": "CVSS:3.1/AV:L/AC:L/PR:N/UI:N/S:U/C:H/I:H/A:H",
		"status": "draft"
	},
	"cwe": "CWE-94",
	"details": [
		"In Python 3.8.4, sys.path restrictions specified in a python38._pth file are ignored, allowing code to be loaded from arbitrary locations. The <executable-name>._pth file (e.g., the python._pth file) is not affected."
	],
	"name": "CVE-2020-15801",
	"package_state": [
		{
			"cpe": "cpe:/o:redhat:enterprise_linux:5",
			"fix_state": "Not affected",
			"package_name": "python",
			"product_name": "Red Hat Enterprise Linux 5"
		},
		{
			"cpe": "cpe:/o:redhat:enterprise_linux:6",
			"fix_state": "Not affected",
			"package_name": "python",
			"product_name": "Red Hat Enterprise Linux 6"
		},
		{
			"cpe": "cpe:/o:redhat:enterprise_linux:7",
			"fix_state": "Not affected",
			"package_name": "python",
			"product_name": "Red Hat Enterprise Linux 7"
		},
		{
			"cpe": "cpe:/o:redhat:enterprise_linux:7",
			"fix_state": "Not affected",
			"package_name": "python3",
			"product_name": "Red Hat Enterprise Linux 7"
		},
		{
			"cpe": "cpe:/o:redhat:enterprise_linux:8",
			"fix_state": "Not affected",
			"package_name": "python27:2.7/python2",
			"product_name": "Red Hat Enterprise Linux 8"
		},
		{
			"cpe": "cpe:/o:redhat:enterprise_linux:8",
			"fix_state": "Not affected",
			"package_name": "python3",
			"product_name": "Red Hat Enterprise Linux 8"
		},
		{
			"cpe": "cpe:/o:redhat:enterprise_linux:8",
			"fix_state": "Not affected",
			"package_name": "python36:3.6/python36",
			"product_name": "Red Hat Enterprise Linux 8"
		},
		{
			"cpe": "cpe:/o:redhat:enterprise_linux:8",
			"fix_state": "Not affected",
			"package_name": "python38:3.8/python38",
			"product_name": "Red Hat Enterprise Linux 8"
		},
		{
			"cpe": "cpe:/a:redhat:quay:3",
			"fix_state": "Not affected",
			"package_name": "python27",
			"product_name": "Red Hat Quay 3"
		},
		{
			"cpe": "cpe:/a:redhat:rhel_software_collections:3",
			"fix_state": "Not affected",
			"package_name": "python27-python",
			"product_name": "Red Hat Software Collections"
		},
		{
			"cpe": "cpe:/a:redhat:rhel_software_collections:3",
			"fix_state": "Not affected",
			"package_name": "rh-python36-python",
			"product_name": "Red Hat Software Collections"
		},
		{
			"cpe": "cpe:/a:redhat:rhel_software_collections:3",
			"fix_state": "Not affected",
			"package_name": "rh-python38-python",
			"product_name": "Red Hat Software Collections"
		}
	],
	"public_date": "2020-07-15T00:00:00Z",
	"references": [
		"https://www.cve.org/CVERecord?id=CVE-2020-15801\nhttps://nvd.nist.gov/vuln/detail/CVE-2020-15801"
	],
	"statement": "This flaw does not affect versions of python shipped with Red Hat Enterprise Linux, Red Hat Software Collections or Red Hat Quay; the vulnerable code exists in a module specific to Microsoft Windows deployment.",
	"threat_severity": "Important"
}
